Workbook

Sheet 對照總表
A1: 聯茂(6213) vs 台燿(6274)｜未來三年損益模型 vs 市場共識（v6：M7+填滿高階產能＋逐季漲價延續至2027）
A2: 報告日期 2026/07/25｜v6：①聯茂 2027H2起 M7+填滿高階線產能、M6削減轉M7（General server由M6轉M7；Low DK布無虞、M7+產能才稀缺）②台燿新增產能全數M7+ ③漲價路徑 26H2 +12.5%/季、27H1 +10%、27H2 +6%、28持平
A3: 方法：CCL價格指數(板廠詢價)＋壓合工時折扣(建滔會議)＋逐月調價路徑(法說guidance)；兩檔完全相同標準
A5: ① 營收對照（億元）
A6: 公司 | B6: 項目 | C6: 2026E | D6: 2027E | E6: 2028E | F6: 26→27 | G6: 27→28
A7: 聯茂 6213 | B7: 本模型營收 | C7: =聯茂6213_月度模型!AL2 -> 534.51 | D7: =聯茂6213_月度模型!AM2 -> 1132.84 | E7: =聯茂6213_月度模型!AN2 -> 1589.64 | F7: =D7/C7-1 -> 1.1193991 | G7: =E7/D7-1 -> 0.40323435
A8: 台燿 6274 | B8: 本模型營收 | C8: =台燿6274_月度模型!AL2 -> 647.62 | D8: =台燿6274_月度模型!AM2 -> 1418.2 | E8: =台燿6274_月度模型!AN2 -> 2027.44 | F8: =D8/C8-1 -> 1.1898644 | G8: =E8/D8-1 -> 0.4295868
A9: （參考）法人共識營收 | B9: 聯茂未取得／台燿 | C9: — | D9: — | E9: — | F9: 台燿共識營收 599.35／1,048.29／1,611.84 億
A11: ② EPS 對照（元）
A12: 公司 | B12: 項目 | C12: 2026E | D12: 2027E | E12: 2028E | F12: 說明
A13: 聯茂 6213 | B13: 本模型 EPS（v6基本情境） | C13: =聯茂6213_月度模型!AL19 -> 12.744113 | D13: =聯茂6213_月度模型!AM19 -> 44.873932 | E13: =聯茂6213_月度模型!AN19 -> 72.209916
B14: 法人共識 EPS | C14: =聯茂6213_月度模型!AO19 -> 9.54 | D14: =聯茂6213_月度模型!AP19 -> 17.14 | E14: =聯茂6213_月度模型!AQ19 -> 14.8 | F14: 優分析 2026/07/10
B15: 差異 % | C15: =C13/C14-1 -> 0.33586094 | D15: =D13/D14-1 -> 1.6180824 | E15: =E13/E14-1 -> 3.8790483 | F15: 正=本模型高於共識
B16: v5版（M6+未填滿產能） | C16: 12.5 | D16: 27.55 | E16: 39 | F16: v6將M7+填滿高階產能後之差異（台燿未變）
A18: 台燿 6274 | B18: 本模型 EPS（v6基本情境） | C18: =台燿6274_月度模型!AL19 -> 32.810012 | D18: =台燿6274_月度模型!AM19 -> 89.093255 | E18: =台燿6274_月度模型!AN19 -> 138.18572
B19: 法人共識 EPS | C19: =台燿6274_月度模型!AO19 -> 35.27 | D19: =台燿6274_月度模型!AP19 -> 76.4 | E19: =台燿6274_月度模型!AQ19 -> 128.95 | F19: 優分析 2026/07/10
B20: 差異 % | C20: =C18/C19-1 -> -0.06974732 | D20: =D18/D19-1 -> 0.16614208 | E20: =E18/E19-1 -> 0.071622514 | F20: 正=本模型高於共識
B21: v5版（M6+未填滿產能） | C21: 32.19 | D21: 77.62 | E21: 116.75 | F21: v6將M7+填滿高階產能後之差異（台燿未變）
A23: ③ 關鍵假設與敏感度
A24: 項目 | B24: 聯茂 6213 | C24: 台燿 6274
A25: 基本情境的核心設定 | B25: 2027H2起M7+填滿高階線(M7 177.8→219.8萬張/月)、M6削減至20→15萬張 ＋ 漲價延續至2027 | C25: 新增產能(235→430萬張)全數配置M7+ ＋ 同一漲價路徑
A26: 換算關鍵參數 | B26: 高階線壓合當量使用率 2026 55%→2027 83%→2028 95%(已逼近上限) | C26: 新增線每張當量2.20~2.45(vs現行1.401)，實產張數打36-43%折
A27: ★最脆弱假設 | B27: M7能否填滿產能：需樹脂288→452噸/月(聯茂另有SABIC/MGC/雙鍵來源) | C27: 毛利率31-34.6%已超越產業紀錄(台光電29.42%)；封頂29.4%則EPS降12-15%
A28: 與公司口徑的張力 | B28: 2026Q4仍為mPPO通路實績(M7 48.7萬張)；2027起改為產能驅動 | C28: 無公司價格guidance，漲價路徑為套用產業路徑
A29: 產能是否撞頂 | B29: 2028已用95%，撞頂。SpaceX訂單需排擠M6或等泰二廠 | C29: 新增產能已全數用於M7+，等同滿配
A30: 與共識的關係 | B30: 遠高於共識（共識未計入mPPO放量與漲價延續）；SpaceX訂單仍為尚未計入的upside | C30: 2027-28已超越共識；意即共識隱含『漲價2026年底即止』
A32: ④ 使用說明
A33: • v3 依 Wallace 指示，把「M7 放量」與「新增產能全高階」由模型外上檔改為基本情境。前版(v2)數字保留在②供對照。
A34: • 所有 EPS／營收為活公式，連結至兩張月度模型分頁；改月度分頁 row2(營收) 或 row3(毛利率)，本表自動重算。
A35: • 「產品組合假設_M6toM9」分頁列出逐年各級距量占比／月出貨／ASP／年營收，並附實際值回填區。
A36: • 2026/01-06 營收為公告實際值；26Q1(聯茂)／26Q1(台燿) 毛利率為財報實際。其餘為推估。
A37: • 本模型為情境版：推估參數佔比高，且兩家的最脆弱假設（聯茂樹脂分流、台燿毛利率天花板）各自可造成 12-18% 的 EPS 差異。

Sheet 產品組合假設_M6toM9
A1: 聯茂／台燿｜M6~M9 出貨量與營收占比假設（v3 基本情境）
A2: 報告日期 2026/07/25｜綠底=模型假設；黃底=請自行回填實際值
A3: 價格指數(板廠詢價)：M4 0.75｜M6 1.00｜M7 1.30｜M7N 2.25｜M8 3.00｜M8U 5.00｜M9 17.00；FR4/M2 0.48
A5: 【聯茂】v4 基本情境 （2026僅H2，因H1為實際值）
A6: 級距 | B6: 價格指數 | C6: 2026 量占比 | D6: 2026 月出貨(萬張) | E6: 2026 ASP(元/張) | F6: 2026 營收占比 | G6: 2027 量占比 | H6: 2027 月出貨(萬張) | I6: 2027 ASP(元/張) | J6: 2027 營收占比 | K6: 2028 量占比 | L6: 2028 月出貨(萬張) | M6: 2028 ASP(元/張) | N6: 2028 營收占比
A7: FR4/M2 | B7: 0.48 | C7: 0.54827179 | D7: 224.5173 | E7: 903.84 | F7: 0.37274526 | G7: 0.43974372 | H7: 190.464 | I7: 1201.44 | J7: 0.24396488 | K7: 0.35898197 | L7: 169.26 | M7: 1352.64 | N7: 0.17283745
A8: M4 | B8: 0.75 | C8: 0.18865266 | D8: 77.253263 | E8: 1412.25 | F8: 0.20040067 | G8: 0.15130967 | H8: 65.536 | I8: 1877.25 | J8: 0.13116391 | K8: 0.12352068 | L8: 58.24 | M8: 2113.5 | N8: 0.092923359
A9: M6 | B9: 1 | C9: 0.15873016 | D9: 65 | E9: 1883 | F9: 0.22481974 | G9: 0.076190476 | H9: 33 | I9: 2503 | J9: 0.088061709 | K9: 0.031813362 | L9: 15 | M9: 2818 | N9: 0.031910494
A10: M7 | B10: 1.3 | C10: 0.10063355 | D10: 41.20944 | E10: 2447.9 | F10: 0.18529391 | G10: 0.32352092 | H10: 140.125 | I10: 3253.9 | J10: 0.4861073 | K10: 0.46617179 | L10: 219.8 | M10: 3663.4 | N10: 0.60787364
A11: M7N | B11: 2.25 | C11: 0 | D11: 0 | E11: 4236.75 | F11: 0 | G11: 0 | H11: 0 | I11: 5631.75 | J11: 0 | K11: 0 | L11: 0 | M11: 6340.5 | N11: 0
A12: M8 | B12: 3 | C12: 0.0036630037 | D12: 1.5 | E12: 5649 | F12: 0.015564443 | G12: 0.0080808081 | H12: 3.5 | I12: 7509 | J12: 0.028019635 | K12: 0.016967126 | L12: 8 | M12: 8454 | N12: 0.05105679
A13: M8U | B13: 5 | C13: 0 | D13: 0 | E13: 9415 | F13: 0 | G13: 0 | H13: 0 | I13: 12515 | J13: 0 | K13: 0 | L13: 0 | M13: 14090 | N13: 0
A14: M9 | B14: 17 | C14: 4.8840049e-05 | D14: 0.02 | E14: 32011 | F14: 0.0011759802 | G14: 0.0011544012 | H14: 0.5 | I14: 42551 | J14: 0.022682561 | K14: 0.0025450689 | L14: 1.2 | M14: 47906 | N14: 0.043398272
A15: M6+ 合計 | B15: — | C15: =SUM(C9:C14) -> 0.26307555 | D15: =SUM(D9:D14) -> 107.72944 | E15: — | F15: =SUM(F9:F14) -> 0.42685407 | G15: =SUM(G9:G14) -> 0.40894661 | H15: =SUM(H9:H14) -> 177.125 | I15: — | J15: =SUM(J9:J14) -> 0.62487121 | K15: =SUM(K9:K14) -> 0.51749735 | L15: =SUM(L9:L14) -> 244 | M15: — | N15: =SUM(N9:N14) -> 0.73423919
A17: 【台燿】v4 基本情境 （2026僅H2，因H1為實際值）
A18: 級距 | B18: 價格指數 | C18: 2026 量占比 | D18: 2026 月出貨(萬張) | E18: 2026 ASP(元/張) | F18: 2026 營收占比 | G18: 2027 量占比 | H18: 2027 月出貨(萬張) | I18: 2027 ASP(元/張) | J18: 2027 營收占比 | K18: 2028 量占比 | L18: 2028 月出貨(萬張) | M18: 2028 ASP(元/張) | N18: 2028 營收占比
A19: FR4/M2 | B19: 0.48 | C19: 0.34777545 | D19: 86.43444 | E19: 1237.44 | F19: 0.15925699 | G19: 0.30868153 | H19: 86.43444 | I19: 1644.48 | J19: 0.12129936 | K19: 0.2771587 | L19: 86.43444 | M19: 1851.36 | N19: 0.094716275
A20: M4 | B20: 0.75 | C20: 0.24460382 | D20: 60.79266 | E20: 1933.5 | F20: 0.17501805 | G20: 0.21710757 | H20: 60.79266 | I20: 2569.5 | J20: 0.1333039 | K20: 0.19493635 | L20: 60.79266 | M20: 2892.75 | N20: 0.10408999
A21: M6 | B21: 1 | C21: 0.14644565 | D21: 36.3969 | E21: 2578 | F21: 0.13971236 | G21: 0.1299835 | H21: 36.3969 | I21: 3426 | J21: 0.10641304 | K21: 0.11670947 | L21: 36.3969 | M21: 3857 | N21: 0.083092331
A22: M7 | B22: 1.3 | C22: 0.13656589 | D22: 33.94143 | E22: 3351.4 | F22: 0.1693729 | G22: 0.16118682 | H22: 45.134196 | I22: 4453.8 | J22: 0.17154557 | K22: 0.16084655 | L22: 50.161447 | M22: 5014.1 | N22: 0.14887095
A23: M7N | B23: 2.25 | C23: 0 | D23: 0 | E23: 5800.5 | F23: 0 | G23: 0 | H23: 0 | I23: 7708.5 | J23: 0 | K23: 0.014917064 | L23: 4.6520209 | M23: 8678.25 | N23: 0.023895753
A24: M8 | B24: 3 | C24: 0.12460919 | D24: 30.96977 | E24: 7734 | F24: 0.35663969 | G24: 0.1721137 | H24: 48.193851 | I24: 10278 | J24: 0.4227108 | K24: 0.20559774 | L24: 64.117509 | M24: 11571 | N24: 0.43913136
A25: M8U | B25: 5 | C25: 0 | D25: 0 | E25: 12890 | F25: 0 | G25: 0.010926883 | H25: 3.0596551 | I25: 17130 | J25: 0.044727326 | K25: 0.029834128 | L25: 9.3040419 | M25: 19285 | N25: 0.10620335
A26: M9 | B26: 17 | C26: 0 | D26: 0 | E26: 43826 | F26: 0 | G26: 0 | H26: 0 | I26: 58242 | J26: 0 | K26: 0 | L26: 0 | M26: 65569 | N26: 0
A27: M6+ 合計 | B27: — | C27: =SUM(C21:C26) -> 0.40762073 | D27: =SUM(D21:D26) -> 101.3081 | E27: — | F27: =SUM(F21:F26) -> 0.66572496 | G27: =SUM(G21:G26) -> 0.4742109 | H27: =SUM(H21:H26) -> 132.7846 | I27: — | J27: =SUM(J21:J26) -> 0.74539674 | K27: =SUM(K21:K26) -> 0.52790495 | L27: =SUM(L21:L26) -> 164.63192 | M27: — | N27: =SUM(N21:N26) -> 0.80119374
A29: 【實際值回填區】季報／法說公布後填此區
A30: 公司 | B30: 期間 | C30: M6+量占比 | D30: M6+營收占比 | E30: M7營收占比 | F30: M8營收占比 | G30: M9是否量產 | H30: blended ASP(季營收÷季產出) | I30: mPPO叫貨(噸) | J30: 備註
A31: 聯茂 | B31: 2026Q3
A32: 聯茂 | B32: 2026Q4
A33: 聯茂 | B33: 2027Q1
A34: 聯茂 | B34: 2027Q2
A35: 聯茂 | B35: 2027Q3
A36: 聯茂 | B36: 2027Q4
A37: 聯茂 | B37: 2028Q1
A38: 聯茂 | B38: 2028Q2
A39: 聯茂 | B39: 2028Q3
A40: 聯茂 | B40: 2028Q4
A42: 台燿 | B42: 2026Q3
A43: 台燿 | B43: 2026Q4
... A51: 台燿 | B51: 2028Q4
...

Sheet 聯茂6213_月度模型
A1: 單位：億元 | B1: 115/01 | C1: 115/02 | D1: 115/03 | E1: 115/04 | F1: 115/05 | G1: 115/06 | H1: 115/07 | I1: 115/08 | J1: 115/09 | K1: 115/10 | L1: 115/11 | M1: 115/12 | N1: 116/01 | O1: 116/02 | P1: 116/03 | Q1: 116/04 | R1: 116/05 | S1: 116/06 | T1: 116/07 | U1: 116/08 | V1: 116/09 | W1: 116/10 | X1: 116/11 | Y1: 116/12 | Z1: 117/01 | AA1: 117/02 | AB1: 117/03 | AC1: 117/04 | AD1: 117/05 | AE1: 117/06 | AF1: 117/07 | AG1: 117/08 | AH1: 117/09 | AI1: 117/10 | AJ1: 117/11 | AK1: 117/12 | AL1: 2026全年 | AM1: 2027全年 | AN1: 2028全年 | AO1: 法人2026共識 | AP1: 法人2027共識 | AQ1: 法人2028共識
A2: 營收 | B2: 31.64 | C2: 26.1 | D2: 33.7 | E2: 35.13 | F2: 38.03 | G2: 42.14 | H2: 46.28 | I2: 48.13 | J2: 51.14 | K2: 58.37 | L2: 60.71 | M2: 63.14 | N2: 67.92 | O2: 72.88 | P2: 78.2 | Q2: 83.67 | R2: 89.53 | S2: 95.57 | T2: 102.36 | U2: 104.37 | V2: 106.41 | W2: 108.5 | X2: 110.63 | Y2: 112.8 | Z2: 131 | AA2: 131 | AB2: 131 | AC2: 131 | AD2: 131 | AE2: 131 | AF2: 133.94 | AG2: 133.94 | AH2: 133.94 | AI2: 133.94 | AJ2: 133.94 | AK2: 133.94 | AL2: =SUM(B2:M2) -> 534.51 | AM2: =SUM(N2:Y2) -> 1132.84 | AN2: =SUM(Z2:AK2) -> 1589.64
A3: 營業毛利率 | B3: 0.1142 | C3: 0.1142 | D3: 0.1142 | E3: 0.195 | F3: 0.195 | G3: 0.195 | H3: 0.198 | I3: 0.198 | J3: 0.198 | K3: 0.205 | L3: 0.205 | M3: 0.205 | N3: 0.245 | O3: 0.245 | P3: 0.245 | Q3: 0.256 | R3: 0.256 | S3: 0.256 | T3: 0.268 | U3: 0.268 | V3: 0.268 | W3: 0.276 | X3: 0.276 | Y3: 0.276 | Z3: 0.288 | AA3: 0.288 | AB3: 0.288 | AC3: 0.292 | AD3: 0.292 | AE3: 0.292 | AF3: 0.295 | AG3: 0.295 | AH3: 0.295 | AI3: 0.298 | AJ3: 0.298 | AK3: 0.298 | AL3: =AL4/AL2 -> 0.18540336 | AM3: =AM4/AM2 -> 0.26305067 | AN3: =AN4/AN2 -> 0.29328606
A4: 營業毛利 | B4: =B2*B3 -> 3.613288 | C4: =C2*C3 -> 2.98062 | D4: =D2*D3 -> 3.84854 | E4: =E2*E3 -> 6.85035 | F4: =F2*F3 -> 7.41585 | G4: =G2*G3 -> 8.2173 | H4: =H2*H3 -> 9.16344 | I4: =I2*I3 -> 9.52974 | ... AK4: =AK2*AK3 -> 39.91412 | AL4: =SUM(B4:M4) -> 99.099948 | AM4: =SUM(N4:Y4) -> 297.99432 | AN4: =SUM(Z4:AK4) -> 466.21926
A5: 營業費用率 | B5: 0.0678 | C5: 0.0678 | D5: 0.0678 | E5: 0.06 | F5: 0.06 | G5: 0.06 | H5: 0.06 | I5: 0.06 | J5: 0.06 | K5: 0.06 | L5: 0.06 | M5: 0.06 | N5: 0.06 | O5: 0.06 | P5: 0.06 | Q5: 0.06 | R5: 0.06 | S5: 0.06 | T5: 0.06 | U5: 0.06 | V5: 0.06 | W5: 0.06 | X5: 0.06 | Y5: 0.06 | Z5: 0.06 | AA5: 0.06 | AB5: 0.06 | AC5: 0.06 | AD5: 0.06 | AE5: 0.06 | AF5: 0.06 | AG5: 0.06 | AH5: 0.06 | AI5: 0.06 | AJ5: 0.06 | AK5: 0.06 | AL5: =AL6/AL2 -> 0.061334366 | AM5: =AM6/AM2 -> 0.06 | AN5: =AN6/AN2 -> 0.06
A6: 營業費用（月） | B6: =B2*B5 -> 2.145192 | C6: =C2*C5 -> 1.76958 | D6: =D2*D5 -> 2.28486 | E6: =E2*E5 -> 2.1078 | F6: =F2*F5 -> 2.2818 | G6: =G2*G5 -> 2.5284 | H6: =H2*H5 -> 2.7768 | I6: =I2*I5 -> 2.8878 | ... AK6: =AK2*AK5 -> 8.0364 | AL6: =SUM(B6:M6) -> 32.783832 | AM6: =SUM(N6:Y6) -> 67.9704 | AN6: =SUM(Z6:AK6) -> 95.3784
A7: 營業利益 | B7: =B4-B6 -> 1.468096 | C7: =C4-C6 -> 1.21104 | D7: =D4-D6 -> 1.56368 | E7: =E4-E6 -> 4.74255 | F7: =F4-F6 -> 5.13405 | G7: =G4-G6 -> 5.6889 | H7: =H4-H6 -> 6.38664 | I7: =I4-I6 -> 6.64194 | ... AN7: =AN4-AN6 -> 370.84086
A8: 營業利益率 | B8: =B7/B2 -> 0.0464 | C8: =C7/C2 -> 0.0464 | D8: =D7/D2 -> 0.0464 | E8: =E7/E2 -> 0.135 | F8: =F7/F2 -> 0.135 | G8: =G7/G2 -> 0.135 | H8: =H7/H2 -> 0.138 | I8: =I7/I2 -> 0.138 | ... AN8: =AN7/AN2 -> 0.23328606
A9: 業外收益 | B9: 0.167 | C9: 0.167 | D9: 0.167 | E9: 0.167 | F9: 0.167 | G9: 0.167 | H9: 0.167 | I9: 0.167 | J9: 0.167 | K9: 0.167 | L9: 0.167 | M9: 0.167 | N9: 0.25 | O9: 0.25 | P9: 0.25 | Q9: 0.25 | R9: 0.25 | S9: 0.25 | T9: 0.25 | U9: 0.25 | V9: 0.25 | W9: 0.25 | X9: 0.25 | Y9: 0.25 | Z9: 0.3 | AA9: 0.3 | AB9: 0.3 | AC9: 0.3 | AD9: 0.3 | AE9: 0.3 | AF9: 0.3 | AG9: 0.3 | AH9: 0.3 | AI9: 0.3 | AJ9: 0.3 | AK9: 0.3 | AL9: =SUM(B9:M9) -> 2.004 | AM9: =SUM(N9:Y9) -> 3 | AN9: =SUM(Z9:AK9) -> 3.6
A10: 稅前淨利率 | B10: =B11/B2 -> 0.051678129 | C10: =C11/C2 -> 0.052798467 | D10: =D11/D2 -> 0.05135549 | E10: =E11/E2 -> 0.13975377 | F10: =F11/F2 -> 0.13939127 | G10: =G11/G2 -> 0.13896298 | H10: =H11/H2 -> 0.14160847 | I10: =I11/I2 -> 0.14146977 | ... AN10: =AN11/AN2 -> 0.23555073
A11: 稅前淨利 | B11: =B7+B9 -> 1.635096 | C11: =C7+C9 -> 1.37804 | D11: =D7+D9 -> 1.73068 | E11: =E7+E9 -> 4.90955 | F11: =F7+F9 -> 5.30105 | G11: =G7+G9 -> 5.8559 | H11: =H7+H9 -> 6.55364 | I11: =I7+I9 -> 6.80894 | ... AN11: =AN7+AN9 -> 374.44086
A12: 所得稅費用 | B12: =B11*0.348 -> 0.56901341 | C12: =C11*0.348 -> 0.47955792 | D12: =D11*0.348 -> 0.60227664 | E12: =E11*0.32 -> 1.571056 | F12: =F11*0.32 -> 1.696336 | G12: =G11*0.32 -> 1.873888 | H12: =H11*0.32 -> 2.0971648 | I12: =I11*0.32 -> 2.1788608 | J12: =J11*0.32 -> 2.3117824 | K12: =K11*0.32 -> 2.761808 | L12: =L11*0.32 -> 2.870384 | M12: =M11*0.32 -> 2.983136 | N12: =N11*0.3 -> 3.84456 | O12: =O11*0.3 -> 4.11984 | P12: =P11*0.3 -> 4.4151 | Q12: =Q11*0.3 -> 4.994796 | R12: =R11*0.3 -> 5.339364 | S12: =S11*0.3 -> 5.694516 | T12: =T11*0.3 -> 6.462264 | U12: =U11*0.3 -> 6.587688 | ... Y12: =Y11*0.3 -> 7.38444 | Z12: =Z11*0.299 -> 9.020232 | AA12: =AA11*0.299 -> 9.020232 | AB12: =AB11*0.299 -> 9.020232 | AC12: =AC11*0.299 -> 9.176908 | AD12: =AD11*0.299 -> 9.176908 | AE12: =AE11*0.299 -> 9.176908 | AF12: =AF11*0.299 -> 9.5009941 | AG12: =AG11*0.299 -> 9.5009941 | ... AK12: =AK11*0.299 -> 9.6211383 | AL12: =SUM(B12:M12) -> 21.995264 | AM12: =SUM(N12:Y12) -> 69.907176 | AN12: =SUM(Z12:AK12) -> 111.95782
A13: 稅後淨利率(全部) | B13: =B14/B2 -> 0.03369414 | C13: =C14/C2 -> 0.034424601 | D13: =D14/D2 -> 0.033483779 | E13: =E14/E2 -> 0.095032565 | F13: =F14/F2 -> 0.094786064 | G13: =G14/G2 -> 0.094494827 | H13: =H14/H2 -> 0.09629376 | I13: =I14/I2 -> 0.096199443 | ... AN13: =AN14/AN2 -> 0.16512106
A14: 稅後淨利（全部） | B14: =B11-B12 -> 1.0660826 | C14: =C11-C12 -> 0.89848208 | D14: =D11-D12 -> 1.1284034 | E14: =E11-E12 -> 3.338494 | F14: =F11-F12 -> 3.604714 | G14: =G11-G12 -> 3.982012 | H14: =H11-H12 -> 4.4564752 | I14: =I11-I12 -> 4.6300792 | ... AN14: =AN11-AN12 -> 262.48304
A15: 歸屬於母公司比例 | B15: 1 | C15: 1 | D15: 1 | E15: 1 | F15: 1 | G15: 1 | H15: 1 | I15: 1 | J15: 1 | K15: 1 | L15: 1 | M15: 1 | N15: 1 | O15: 1 | P15: 1 | Q15: 1 | R15: 1 | S15: 1 | T15: 1 | U15: 1 | V15: 1 | W15: 1 | X15: 1 | Y15: 1 | Z15: 1 | AA15: 1 | AB15: 1 | AC15: 1 | AD15: 1 | AE15: 1 | AF15: 1 | AG15: 1 | AH15: 1 | AI15: 1 | AJ15: 1 | AK15: 1 | AL15: 1 | AM15: 1 | AN15: 1
A16: 稅後淨利率(歸母) | B16: =B17/B2 -> 0.03369414 | C16: =C17/C2 -> 0.034424601 | D16: =D17/D2 -> 0.033483779 | E16: =E17/E2 -> 0.095032565 | F16: =F17/F2 -> 0.094786064 | G16: =G17/G2 -> 0.094494827 | H16: =H17/H2 -> 0.09629376 | I16: =I17/I2 -> 0.096199443 | ... AN16: =AN17/AN2 -> 0.16512106
A17: 稅後淨利（歸屬於母公司） | B17: =B14*B15 -> 1.0660826 | C17: =C14*C15 -> 0.89848208 | D17: =D14*D15 -> 1.1284034 | E17: =E14*E15 -> 3.338494 | F17: =F14*F15 -> 3.604714 | G17: =G14*G15 -> 3.982012 | H17: =H14*H15 -> 4.4564752 | I17: =I14*I15 -> 4.6300792 | ... AN17: =AN14*AN15 -> 262.48304
A18: 股數（需計算稀釋） | B18: 3.635 | C18: 3.635 | D18: 3.635 | E18: 3.635 | F18: 3.635 | G18: 3.635 | H18: 3.635 | I18: 3.635 | J18: 3.635 | K18: 3.635 | L18: 3.635 | M18: 3.635 | N18: 3.635 | O18: 3.635 | P18: 3.635 | Q18: 3.635 | R18: 3.635 | S18: 3.635 | T18: 3.635 | U18: 3.635 | V18: 3.635 | W18: 3.635 | X18: 3.635 | Y18: 3.635 | Z18: 3.635 | AA18: 3.635 | AB18: 3.635 | AC18: 3.635 | AD18: 3.635 | AE18: 3.635 | AF18: 3.635 | AG18: 3.635 | AH18: 3.635 | AI18: 3.635 | AJ18: 3.635 | AK18: 3.635 | AL18: 3.635 | AM18: 3.635 | AN18: 3.635
A19: EPS | B19: =B17/B18 -> 0.29328269 | C19: =C17/C18 -> 0.24717526 | D19: =D17/D18 -> 0.31042733 | E19: =E17/E18 -> 0.91843026 | F19: =F17/F18 -> 0.99166823 | G19: =G17/G18 -> 1.0954641 | H19: =H17/H18 -> 1.2259904 | I19: =I17/I18 -> 1.2737494 | ... AN19: =AN17/AN18 -> 72.209916 | AO19: 9.54 | AP19: 17.14 | AQ19: 14.8
A20: EPS每季 | B20: =SUM(B19:D19) -> 0.85088529 | E20: =SUM(E19:G19) -> 3.0055626 | H20: =SUM(H19:J19) -> 3.8511945 | K20: =SUM(K19:M19) -> 5.036471 | N20: =SUM(N19:P19) -> 7.9464924 | Q20: =SUM(Q19:S19) -> 10.288925 | T20: =SUM(T19:V19) -> 12.687258 | W20: =SUM(W19:Y19) -> 13.951256 | Z20: =SUM(Z19:AB19) -> 17.453454 | AC20: =SUM(AC19:AE19) -> 17.75661 | AF20: =SUM(AF19:AH19) -> 18.383691 | AI20: =SUM(AI19:AK19) -> 18.616161
A26: 年EPS | B26: =B20+E20+H20+K20 -> 12.744113 | N26: =N20+Q20+T20+W20 -> 44.873932 | Z26: =Z20+AC20+AF20+AI20 -> 72.209916
A28: Note: | B28: 【v3 20260725｜依Wallace指示改為基本情境】mPPO【交聯茂總量】自2026/10起達100噸/月（Wallace方交貨50噸＋元鴻配套50噸）。逐月路徑：4-5月20噸→6月32噸→7-8月64噸→9月80噸→10月起100噸。前版(v3)誤把100噸當成宜蘭出貨再×2＝200噸，M7高估一倍，本版已修正。
B29: 【M7張數換算】每張耗樹脂0.113kg（41×49吋=1.296m²、4mil介電層、密度~1.95、樹脂含量45%）；mPPO同時用於CCL基板核心與PP半固化片，PP按捲計價不佔『萬張』，故設流向CCL 55%。100噸×55%÷0.113 = M7約48.7萬張/月（2026年10月起，為2026H2之量體依據）。
B30: 【v6核心修正‧依Wallace指示】2027H2起 M7+ 填滿高階線產能，並削減M6轉M7（General server本身也在由M6轉M7；Low DK布供應無虞、M7+產能才是稀缺資源）。M7路徑：2026Q4 48.7萬張 → 2027H1線性爬坡 → 2027H2起177.8萬張 → 2028 219.8萬張；M6同步由65萬張降至2027H2的20萬張、2028的15萬張。高階線壓合當量使用率：2026 55%→2027 83%→2028 95%（已逼近上限）。
B31: 【樹脂需求反算‧供驗證】填滿產能所需M7樹脂：2027約288噸/月、2028約452噸/月（M7張數×0.113kg÷流向CCL 55%），為Wallace通路(宜蘭50+元鴻50=100噸)的2.9~4.5倍。聯茂另有SABIC NORYL SA9000、MGC OPE-2ST、雙鍵等來源，此倍數合理，故mPPO 100噸應視為『斜率領先指標』而非量體上限。
B32: 【毛利率】26Q1 11.42%實際；26Q2-Q4為法說guidance（19.5/19.8/20.5%）；2027 24.5-27.6%、2028 28.8-29.8%，隨漲價延續＋M7填滿產能同步上調。2028仍封頂於公司長線口徑『玻纖布緩解後30%可達成』之下（最高29.8%），保留保守墊。
B33: 【價格路徑‧v5核心修正】前版(v4)僅2026H2放每季+10%，2027壓到+2.7%/季、2028歸零，那是三情境機率加權後的殘值而非公司口徑，與證據不符。本版改為：2026H2 +12.5%/季(法說『每季10-15%』取中)、2027H1 +10%/季、2027H2 +6%/季、2028 持平。依據：法說『接下來每一季都會漲』『接下來12個月(至2027年中)緩解都不容易』；建滔會議『電子布到27年供需不會太快恢復平衡』。2028仍設持平，保守墊留在最遠一年。
B34: 【尚未計入的upside】2027年SpaceX低軌衛星訂單（法說：明年起顯著貢獻，材料M4/M6/M7）尚未納入本模型，待訂單能見度明朗後再上修。 【最脆弱三點】①M7能否真的填滿高階產能（需樹脂供應與客戶認證同步到位；2028高階線已用95%，無再上修空間）②2027後漲價循環壽命 ③毛利率2028達29.8%已貼近公司長線上限。

Sheet 台燿6274_月度模型
A1: 單位：億元 | B1: 115/01 | C1: 115/02 | D1: 115/03 | E1: 115/04 | F1: 115/05 | G1: 115/06 | H1: 115/07 | I1: 115/08 | J1: 115/09 | K1: 115/10 | L1: 115/11 | M1: 115/12 | N1: 116/01 | O1: 116/02 | P1: 116/03 | Q1: 116/04 | R1: 116/05 | S1: 116/06 | T1: 116/07 | U1: 116/08 | V1: 116/09 | W1: 116/10 | X1: 116/11 | Y1: 116/12 | Z1: 117/01 | AA1: 117/02 | AB1: 117/03 | AC1: 117/04 | AD1: 117/05 | AE1: 117/06 | AF1: 117/07 | AG1: 117/08 | AH1: 117/09 | AI1: 117/10 | AJ1: 117/11 | AK1: 117/12 | AL1: 2026全年 | AM1: 2027全年 | AN1: 2028全年 | AO1: 法人2026共識 | AP1: 法人2027共識 | AQ1: 法人2028共識
A2: 營收 | B2: 33.5 | C2: 29.24 | D2: 37.8 | E2: 46.1 | F2: 47.94 | G2: 48.95 | H2: 54.98 | I2: 61.04 | J2: 67.19 | K2: 69.88 | L2: 73.68 | M2: 77.32 | N2: 83.51 | O2: 89.4 | P2: 95.59 | Q2: 102.09 | R2: 108.9 | S2: 116.05 | T2: 122.03 | U2: 128.2 | V2: 134.57 | W2: 141.14 | X2: 145.91 | Y2: 150.81 | Z2: 155.83 | AA2: 158.46 | AB2: 161.1 | AC2: 163.73 | AD2: 166.36 | AE2: 169 | AF2: 171.63 | AG2: 173.21 | AH2: 174.27 | AI2: 176.37 | AJ2: 177.95 | AK2: 179.53 | AL2: =SUM(B2:M2) -> 647.62 | AM2: =SUM(N2:Y2) -> 1418.2 | AN2: =SUM(Z2:AK2) -> 2027.44
A3: 營業毛利率 | B3: 0.2515 | C3: 0.2515 | D3: 0.2515 | E3: 0.265 | F3: 0.265 | G3: 0.265 | H3: 0.28 | I3: 0.28 | J3: 0.28 | K3: 0.29 | L3: 0.29 | M3: 0.29 | N3: 0.315 | O3: 0.315 | P3: 0.315 | Q3: 0.32 | R3: 0.32 | S3: 0.32 | T3: 0.325 | U3: 0.325 | V3: 0.325 | W3: 0.33 | X3: 0.33 | Y3: 0.33 | Z3: 0.34 | AA3: 0.34 | AB3: 0.34 | AC3: 0.343 | AD3: 0.343 | AE3: 0.343 | AF3: 0.346 | AG3: 0.346 | AH3: 0.346 | AI3: 0.349 | AJ3: 0.349 | AK3: 0.349 | AL3: =AL4/AL2 -> 0.27567425 | AM3: =AM4/AM2 -> 0.32349746 | AN3: =AN4/AN2 -> 0.34464457
A4: 營業毛利 | B4: =B2*B3 -> 8.42525 | C4: =C2*C3 -> 7.35386 | D4: =D2*D3 -> 9.5067 | E4: =E2*E3 -> 12.2165 | F4: =F2*F3 -> 12.7041 | G4: =G2*G3 -> 12.97175 | H4: =H2*H3 -> 15.3944 | I4: =I2*I3 -> 17.0912 | ... AK4: =AK2*AK3 -> 62.65597 | AL4: =SUM(B4:M4) -> 178.53216 | AM4: =SUM(N4:Y4) -> 458.7841 | AN4: =SUM(Z4:AK4) -> 698.74618
A5: 營業費用率 | B5: 0.0697 | C5: 0.0697 | D5: 0.0697 | E5: 0.0697 | F5: 0.0697 | G5: 0.0697 | H5: 0.0697 | I5: 0.0697 | J5: 0.0697 | K5: 0.0697 | L5: 0.0697 | M5: 0.0697 | N5: 0.0697 | O5: 0.0697 | P5: 0.0697 | Q5: 0.0697 | R5: 0.0697 | S5: 0.0697 | T5: 0.0697 | U5: 0.0697 | V5: 0.0697 | W5: 0.0697 | X5: 0.0697 | Y5: 0.0697 | Z5: 0.0697 | AA5: 0.0697 | AB5: 0.0697 | AC5: 0.0697 | AD5: 0.0697 | AE5: 0.0697 | AF5: 0.0697 | AG5: 0.0697 | AH5: 0.0697 | AI5: 0.0697 | AJ5: 0.0697 | AK5: 0.0697 | AL5: =AL6/AL2 -> 0.0697 | AM5: =AM6/AM2 -> 0.0697 | AN5: =AN6/AN2 -> 0.0697
A6: 營業費用（月） | B6: =B2*B5 -> 2.33495 | C6: =C2*C5 -> 2.038028 | D6: =D2*D5 -> 2.63466 | E6: =E2*E5 -> 3.21317 | F6: =F2*F5 -> 3.341418 | G6: =G2*G5 -> 3.411815 | H6: =H2*H5 -> 3.832106 | I6: =I2*I5 -> 4.254488 | ... AK6: =AK2*AK5 -> 12.513241 | AL6: =SUM(B6:M6) -> 45.139114 | AM6: =SUM(N6:Y6) -> 98.84854 | AN6: =SUM(Z6:AK6) -> 141.31257
A7: 營業利益 | B7: =B4-B6 -> 6.0903 | C7: =C4-C6 -> 5.315832 | D7: =D4-D6 -> 6.87204 | E7: =E4-E6 -> 9.00333 | F7: =F4-F6 -> 9.362682 | G7: =G4-G6 -> 9.559935 | H7: =H4-H6 -> 11.562294 | I7: =I4-I6 -> 12.836712 | ... AN7: =AN4-AN6 -> 557.43361
A8: 營業利益率 | B8: =B7/B2 -> 0.1818 | C8: =C7/C2 -> 0.1818 | D8: =D7/D2 -> 0.1818 | E8: =E7/E2 -> 0.1953 | F8: =F7/F2 -> 0.1953 | G8: =G7/G2 -> 0.1953 | H8: =H7/H2 -> 0.2103 | I8: =I7/I2 -> 0.2103 | ... AN8: =AN7/AN2 -> 0.27494457
A9: 業外收益 | B9: -0.15 | C9: -0.15 | D9: -0.15 | E9: -0.15 | F9: -0.15 | G9: -0.15 | H9: -0.15 | I9: -0.15 | J9: -0.15 | K9: -0.15 | L9: -0.15 | M9: -0.15 | N9: -0.217 | O9: -0.217 | P9: -0.217 | Q9: -0.217 | R9: -0.217 | S9: -0.217 | T9: -0.217 | U9: -0.217 | V9: -0.217 | W9: -0.217 | X9: -0.217 | Y9: -0.217 | Z9: -0.267 | AA9: -0.267 | AB9: -0.267 | AC9: -0.267 | AD9: -0.267 | AE9: -0.267 | AF9: -0.267 | AG9: -0.267 | AH9: -0.267 | AI9: -0.267 | AJ9: -0.267 | AK9: -0.267 | AL9: =SUM(B9:M9) -> -1.8 | AM9: =SUM(N9:Y9) -> -2.604 | AN9: =SUM(Z9:AK9) -> -3.204
A10: 稅前淨利率 | B10: =B11/B2 -> 0.17732239 | C10: =C11/C2 -> 0.17667004 | D10: =D11/D2 -> 0.17783175 | E10: =E11/E2 -> 0.1920462 | F10: =F11/F2 -> 0.19217109 | G10: =G11/G2 -> 0.19223565 | H10: =H11/H2 -> 0.20757174 | I10: =I11/I2 -> 0.2078426 | ... AN10: =AN11/AN2 -> 0.27336425
A11: 稅前淨利 | B11: =B7+B9 -> 5.9403 | C11: =C7+C9 -> 5.165832 | D11: =D7+D9 -> 6.72204 | E11: =E7+E9 -> 8.85333 | F11: =F7+F9 -> 9.212682 | G11: =G7+G9 -> 9.409935 | H11: =H7+H9 -> 11.412294 | I11: =I7+I9 -> 12.686712 | ... AN11: =AN7+AN9 -> 554.22961
A12: 所得稅費用 | B12: =B11*0.28 -> 1.663284 | C12: =C11*0.28 -> 1.446433 | D12: =D11*0.28 -> 1.8821712 | E12: =E11*0.28 -> 2.4789324 | F12: =F11*0.28 -> 2.579551 | G12: =G11*0.28 -> 2.6347818 | H12: =H11*0.28 -> 3.1954423 | I12: =I11*0.28 -> 3.5522794 | ... AK12: =AK11*0.28 -> 13.965204 | AL12: =SUM(B12:M12) -> 36.846053 | AM12: =SUM(N12:Y12) -> 100.05284 | AN12: =SUM(Z12:AK12) -> 155.18429
A13: 稅後淨利率(全部) | B13: =B14/B2 -> 0.12767212 | C13: =C14/C2 -> 0.12720243 | D13: =D14/D2 -> 0.12803886 | E13: =E14/E2 -> 0.13827327 | F13: =F14/F2 -> 0.13836318 | G13: =G14/G2 -> 0.13840967 | H13: =H14/H2 -> 0.14945165 | I13: =I14/I2 -> 0.14964667 | ... AN13: =AN14/AN2 -> 0.19682226
A14: 稅後淨利（全部） | B14: =B11-B12 -> 4.277016 | C14: =C11-C12 -> 3.719399 | D14: =D11-D12 -> 4.8398688 | E14: =E11-E12 -> 6.3743976 | F14: =F11-F12 -> 6.633131 | G14: =G11-G12 -> 6.7751532 | H14: =H11-H12 -> 8.2168517 | I14: =I11-I12 -> 9.1344326 | ... AN14: =AN11-AN12 -> 399.04532
A15: 歸屬於母公司比例 | B15: 1 | C15: 1 | D15: 1 | E15: 1 | F15: 1 | G15: 1 | H15: 1 | I15: 1 | J15: 1 | K15: 1 | L15: 1 | M15: 1 | N15: 1 | O15: 1 | P15: 1 | Q15: 1 | R15: 1 | S15: 1 | T15: 1 | U15: 1 | V15: 1 | W15: 1 | X15: 1 | Y15: 1 | Z15: 1 | AA15: 1 | AB15: 1 | AC15: 1 | AD15: 1 | AE15: 1 | AF15: 1 | AG15: 1 | AH15: 1 | AI15: 1 | AJ15: 1 | AK15: 1 | AL15: 1 | AM15: 1 | AN15: 1
A16: 稅後淨利率(歸母) | B16: =B17/B2 -> 0.12767212 | C16: =C17/C2 -> 0.12720243 | D16: =D17/D2 -> 0.12803886 | E16: =E17/E2 -> 0.13827327 | F16: =F17/F2 -> 0.13836318 | G16: =G17/G2 -> 0.13840967 | H16: =H17/H2 -> 0.14945165 | I16: =I17/I2 -> 0.14964667 | ... AN16: =AN17/AN2 -> 0.19682226
A17: 稅後淨利（歸屬於母公司） | B17: =B14*B15 -> 4.277016 | C17: =C14*C15 -> 3.719399 | D17: =D14*D15 -> 4.8398688 | E17: =E14*E15 -> 6.3743976 | F17: =F14*F15 -> 6.633131 | G17: =G14*G15 -> 6.7751532 | H17: =H14*H15 -> 8.2168517 | I17: =I14*I15 -> 9.1344326 | ... AN17: =AN14*AN15 -> 399.04532
A18: 股數（需計算稀釋） | B18: 2.8877464 | C18: 2.8877464 | D18: 2.8877464 | E18: 2.8877464 | F18: 2.8877464 | G18: 2.8877464 | H18: 2.8877464 | I18: 2.8877464 | J18: 2.8877464 | K18: 2.8877464 | L18: 2.8877464 | M18: 2.8877464 | N18: 2.8877464 | O18: 2.8877464 | P18: 2.8877464 | Q18: 2.8877464 | R18: 2.8877464 | S18: 2.8877464 | T18: 2.8877464 | U18: 2.8877464 | V18: 2.8877464 | W18: 2.8877464 | X18: 2.8877464 | Y18: 2.8877464 | Z18: 2.8877464 | AA18: 2.8877464 | AB18: 2.8877464 | AC18: 2.8877464 | AD18: 2.8877464 | AE18: 2.8877464 | AF18: 2.8877464 | AG18: 2.8877464 | AH18: 2.8877464 | AI18: 2.8877464 | AJ18: 2.8877464 | AK18: 2.8877464 | AL18: 2.8877464 | AM18: 2.8877464 | AN18: 2.8877464
A19: EPS | B19: =B17/B18 -> 1.4810913 | C19: =C17/C18 -> 1.2879937 | D19: =D17/D18 -> 1.676002 | E19: =E17/E18 -> 2.2073952 | F19: =F17/F18 -> 2.2969923 | G19: =G17/G18 -> 2.3461732 | H19: =H17/H18 -> 2.8454201 | I19: =I17/I18 -> 3.16317 | ... AN19: =AN17/AN18 -> 138.18572 | AO19: 35.27 | AP19: 76.4 | AQ19: 128.95
A20: EPS每季 | B20: =SUM(B19:D19) -> 4.445087 | E20: =SUM(E19:G19) -> 6.8505607 | H20: =SUM(H19:J19) -> 9.494229 | K20: =SUM(K19:M19) -> 12.020135 | N20: =SUM(N19:P19) -> 16.25928 | Q20: =SUM(Q19:S19) -> 20.247319 | T20: =SUM(T19:V19) -> 24.331665 | W20: =SUM(W19:Y19) -> 28.254992 | Z20: =SUM(Z19:AB19) -> 31.838593 | AC20: =SUM(AC19:AE19) -> 33.809137 | AF20: =SUM(AF19:AH19) -> 35.561623 | AI20: =SUM(AI19:AK19) -> 36.97637
A26: 年EPS | B26: =B20+E20+H20+K20 -> 32.810012 | N26: =N20+Q20+T20+W20 -> 89.093255 | Z26: =Z20+AC20+AF20+AI20 -> 138.18572
A28: Note: | B28: 【v3 20260725｜依Wallace指示改為基本情境】基礎產能235萬張維持26Q1組合，所有新增產能（→295→380→430萬張）全數配置M7+。
B29: 【產能換算】新增銘牌張數係以現行組合(每張1.401當量)定義；改走M7+後每張當量升至2.20~2.45，故實際可產張數需乘以1.401/2.20~2.45（約-36%~-43%）。2028總產出約322萬張/月。
B30: 【重要發現】此設定下2026-2027營收(636/1255億)已超越法人共識(599/1048億)——與Wallace 07/18『情境_增量全給M6+』分頁的結論一致：法人共識本質上就是『新產能全配高階』這條劇本。
B31: 【⚠️毛利率已超越產業紀錄】本版2027-28毛利率設31-34.6%，已高於全產業最高之台光電29.42%。理由是ELL+SLL營收占比升至76-82%，但此為推估、非公司揭露之分部毛利率，屬本模型最脆弱假設。若封頂於29.4%，2027-28 EPS約降12-15%。
B32: 【稅率】採公司實際有效稅率28%；若泰國BOI降至20%，EPS約+11%。
B33: 【與聯茂的方法一致性‧v5】價格路徑（26H2 +12.5%/季、27H1 +10%、27H2 +6%、28持平）、價格指數階梯、壓合工時折扣三者與聯茂完全相同；台燿無公司層級價格guidance，其漲價路徑為套用產業路徑（推估）。前版2027僅+2.7%/季，與建滔『27年供需仍難完全解決』不一致，本版已修正。
B34: 【最脆弱三點】①毛利率能否突破產業紀錄 ②新增產能是否真能全數配置M7+（受玻纖布配額限制）③有效稅率。

Sheet 漲價路徑敏感度
A1: 漲價路徑敏感度｜其餘假設全部不動
A2: 單位：EPS(元)。★=v6基本情境採用。毛利率在各路徑下維持不變（保守處理），實務上漲價越大毛利率同向擴張，故差距為低估
A4: 漲價路徑（M6當量價季增率） | B4: 公司 | C4: 2026E | D4: 2027E | E4: 2028E | F4: 備註
A5: v5版：M6+未填滿產能(M7僅48.7萬張) | B5: 聯茂 | C5: 12.74 | D5: 35.65 | E5: 52.9 | F5: M7受限於單一樹脂通路，低估
B6: 台燿 | C6: 32.81 | D6: 89.09 | E6: 138.19
A7: ★v6基本：M7+填滿高階產能＋漲價延續 | B7: 聯茂 | C7: 12.74 | D7: 44.87 | E7: 72.21 | F7: 聯茂2027H2起M7 177.8萬張；台燿未變
B8: 台燿 | C8: 32.81 | D8: 89.09 | E8: 138.19
A9: 溫和：26H2+10%、27H1+8%、27H2+4%、28 -2%/季 | B9: 聯茂 | C9: 12.53 | D9: 29.49 | E9: 41.88 | F9: 若漲價提前鈍化
B10: 台燿 | C10: 32.14 | D10: 73.29 | E10: 108.93
A11: 極端：全期+12.5%/季不衰減 | B11: 聯茂 | C11: 12.74 | D11: 34.61 | E11: 75.25 | F11: 僅供上界參考，物理上不可持續
B12: 台燿 | C12: 32.7 | D12: 86.88 | E12: 198.77
A14: 法人共識 | B14: 聯茂 | C14: 9.54 | D14: 17.14 | E14: 14.8
B15: 台燿 | C15: 35.27 | D15: 76.4 | E15: 128.95
A17: 【證據盤點：漲價循環會延續多久】
A18: • 聯茂法說(07/02)：『接下來漲價的模式應該還是一樣，每一季都會漲』『下半年每季保守抓10到15%』
A19: • 聯茂法說：『我們覺得接下來整理有到十二個月可能都還不容易』（自2026/07起算 → 延續至2027年中）
A20: • 聯茂法說：『如果玻纖布一年之後沒那麼缺，30%毛利率可達成；但以現在看6到12個月不會完全緩解』
A21: • 建滔專家會議(06/20)：『電子布到27年的供需預計不會太快恢復平衡』『27年供需問題仍難以完全解決』
A22: • 建滔：織布機為最大瓶頸，Toyota全球年產值僅約2000台；高階布擠壓傳統布產能
A23: • 建滔：A公司26H1已漲價5次、累計70-80%，『2H26進入旺季後漲價將更容易』
A24: • → 所有一手來源都指向「至少延續到2027年年中」。v5 據此把2027納入漲價，2028仍設持平作為保守墊。
